<?xml version="1.0" encoding="UTF-8"?>
<testng-results skipped="0" failed="1" total="1" passed="0">
  <reporter-output>
  </reporter-output>
  <suite name="Default suite" duration-ms="38677" started-at="2018-12-26T09:47:59Z" finished-at="2018-12-26T09:48:37Z">
    <groups>
    </groups>
    <test name="Default test" duration-ms="38677" started-at="2018-12-26T09:47:59Z" finished-at="2018-12-26T09:48:37Z">
      <class name="tests.TestCaseLogin">
        <test-method status="PASS" signature="setUpSheetData()[pri:0, instance:tests.TestCaseLogin@224edc67]" name="setUpSheetData" is-config="true" duration-ms="505" started-at="2018-12-26T16:47:59Z" finished-at="2018-12-26T16:47:59Z">
          <reporter-output>
          </reporter-output>
        </test-method> <!-- setUpSheetData -->
        <test-method status="PASS" signature="setUp()[pri:0, instance:tests.TestCaseLogin@224edc67]" name="setUp" is-config="true" duration-ms="6959" started-at="2018-12-26T16:47:59Z" finished-at="2018-12-26T16:48:06Z">
          <reporter-output>
          </reporter-output>
        </test-method> <!-- setUp -->
        <test-method status="FAIL" signature="checkValidate()[pri:0, instance:tests.TestCaseLogin@224edc67]" name="checkValidate" duration-ms="30166" started-at="2018-12-26T16:48:06Z" finished-at="2018-12-26T16:48:36Z">
          <exception class="java.lang.AssertionError">
            <message>
              <![CDATA[expected [true] but found [false]]]>
            </message>
            <full-stacktrace>
              <![CDATA[java.lang.AssertionError: expected [true] but found [false]
	at org.testng.Assert.fail(Assert.java:94)
	at org.testng.Assert.failNotEquals(Assert.java:494)
	at org.testng.Assert.assertTrue(Assert.java:42)
	at org.testng.Assert.assertTrue(Assert.java:52)
	at util.Utils.compareText(Utils.java:75)
	at tests.TestCaseLogin.checkValidate(TestCaseLogin.java:131)
	at sun.reflect.NativeMethodAccessorImpl.invoke0(Native Method)
	at sun.reflect.NativeMethodAccessorImpl.invoke(Unknown Source)
	at sun.reflect.DelegatingMethodAccessorImpl.invoke(Unknown Source)
	at java.lang.reflect.Method.invoke(Unknown Source)
	at org.testng.internal.MethodInvocationHelper.invokeMethod(MethodInvocationHelper.java:85)
	at org.testng.internal.Invoker.invokeMethod(Invoker.java:696)
	at org.testng.internal.Invoker.invokeTestMethod(Invoker.java:882)
	at org.testng.internal.Invoker.invokeTestMethods(Invoker.java:1189)
	at org.testng.internal.TestMethodWorker.invokeTestMethods(TestMethodWorker.java:124)
	at org.testng.internal.TestMethodWorker.run(TestMethodWorker.java:108)
	at org.testng.TestRunner.privateRun(TestRunner.java:767)
	at org.testng.TestRunner.run(TestRunner.java:617)
	at org.testng.SuiteRunner.runTest(SuiteRunner.java:348)
	at org.testng.SuiteRunner.runSequentially(SuiteRunner.java:343)
	at org.testng.SuiteRunner.privateRun(SuiteRunner.java:305)
	at org.testng.SuiteRunner.run(SuiteRunner.java:254)
	at org.testng.SuiteRunnerWorker.runSuite(SuiteRunnerWorker.java:52)
	at org.testng.SuiteRunnerWorker.run(SuiteRunnerWorker.java:86)
	at org.testng.TestNG.runSuitesSequentially(TestNG.java:1224)
	at org.testng.TestNG.runSuitesLocally(TestNG.java:1149)
	at org.testng.TestNG.run(TestNG.java:1057)
	at org.testng.remote.AbstractRemoteTestNG.run(AbstractRemoteTestNG.java:114)
	at org.testng.remote.RemoteTestNG.initAndRun(RemoteTestNG.java:251)
	at org.testng.remote.RemoteTestNG.main(RemoteTestNG.java:77)
]]>
            </full-stacktrace>
          </exception> <!-- java.lang.AssertionError -->
          <reporter-output>
          </reporter-output>
        </test-method> <!-- checkValidate -->
        <test-method status="PASS" signature="tearDown()[pri:0, instance:tests.TestCaseLogin@224edc67]" name="tearDown" is-config="true" duration-ms="1036" started-at="2018-12-26T16:48:36Z" finished-at="2018-12-26T16:48:37Z">
          <reporter-output>
          </reporter-output>
        </test-method> <!-- tearDown -->
      </class> <!-- tests.TestCaseLogin -->
    </test> <!-- Default test -->
  </suite> <!-- Default suite -->
</testng-results>
